Workbook

Sheet Lançamentos de despesas
A1: Data do vencimento | B1: Data da emissão | C1: Data do pagamento | D1: Fornecedor | E1: Status | F1: Forma de pagamento | G1: Banco/conta | H1: Descrição | I1: Valor | J1: Valor descontos | K1: Valor pago | L1: Recorrência | M1: Parcelas | N1: Classificação | O1: MÊS/ANO VENCIMENTO | P1: MÊS/ANO PAGAMENTO | Q1: SUBCATEGORIA | R1: CATEGORIA | S1: DIA DO VENCIMENTO | T1: MÊS VENCIMENTO | U1: ANO VENCIMENTO | V1: DIA DO pagamento | W1: mes pagamento | X1: ano pagamento
A2: 45505 | C2: =IF(E2="pago",A2,"") -> 45505 | D2: ADELINO ALVES - ALUGUEL GALPÃO | E2: Pago | F2: Pix | G2: BANCO DO BRASIL - 65204-0 | H2: ALUGUEL | I2: 6000.63 | K2: =if(E2="pago",(I2-J2),"") -> 6000.63 | L2: Mensal | N2: ALUGUEIS | O2: =if(A2="","", TEXT(A2,"mm/yyyy")) -> 08/2024 | P2: =if(C2="","", TEXT(C2,"mm/yyyy")) -> 08/2024 | Q2: {=IFERROR(XLOOKUP(N2,'Classificação'!A:A,'Classificação'!B:B),"")} -> DESPESAS COM OCUPAÇÃO | R2: {=IFERROR(XLOOKUP(Q2,'Classificação'!B:B,'Classificação'!C:C),"")} -> DESPESAS FIXAS (-) | S2: =iferror(DAY(A2),"") -> 1 | T2: =iferror(MONTH(O2),"") -> 8 | U2: =iferror(YEAR(O2),"") -> 2024 | V2: =if(C2="","", IFERROR(DAY(C2),"")) -> 1 | W2: =if(C2="","",IFERROR(MONTH(C2),"")) -> 8 | X2: =if(C2="","",iferror(YEAR(C2),"")) -> 2024
A3: 45506 | C3: =IF(E3="pago",A3,"") -> 45506 | D3: RIVER FREIGHT LOGISTICS SERVICES | E3: Pago | F3: Transferência bancária | G3: BANCO DO BRASIL - 65204-0 | H3: PGTO DE IMPOSTOS AEREO COMPRA CHINA BROCAS | I3: 7610 | K3: =if(E3="pago",(I3-J3),"") -> 7610 | L3: Única | N3: COMPRA DE MERCADORIA | O3: =if(A3="","", TEXT(A3,"mm/yyyy")) -> 08/2024 | P3: =if(C3="","", TEXT(C3,"mm/yyyy")) -> 08/2024 | Q3: {=IFERROR(XLOOKUP(N3,'Classificação'!A:A,'Classificação'!B:B),"")} -> COMPRA DE MERCADORIA | R3: {=IFERROR(XLOOKUP(Q3,'Classificação'!B:B,'Classificação'!C:C),"")} -> CUSTOS VARIÁVEIS | S3: =iferror(DAY(A3),"") -> 2 | T3: =iferror(MONTH(O3),"") -> 8 | U3: =iferror(YEAR(O3),"") -> 2024 | V3: =if(C3="","", IFERROR(DAY(C3),"")) -> 2 | W3: =if(C3="","",IFERROR(MONTH(C3),"")) -> 8 | X3: =if(C3="","",iferror(YEAR(C3),"")) -> 2024
A4: 45506 | C4: =IF(E4="pago",A4,"") -> 45506 | D4: ELAINE CRISTINA DE MELO | E4: Pago | F4: Transferência bancária | G4: MERCADO PAGO SINCE - 9511092439-1 | I4: 4000 | K4: =if(E4="pago",(I4-J4),"") -> 4000 | L4: Única | N4: SALARIOS | O4: =if(A4="","", TEXT(A4,"mm/yyyy")) -> 08/2024 | P4: =if(C4="","", TEXT(C4,"mm/yyyy")) -> 08/2024 | Q4: {=IFERROR(XLOOKUP(N4,'Classificação'!A:A,'Classificação'!B:B),"")} -> DESPESAS COM PESSOAL | R4: {=IFERROR(XLOOKUP(Q4,'Classificação'!B:B,'Classificação'!C:C),"")} -> DESPESAS FIXAS (-) | S4: =iferror(DAY(A4),"") -> 2 | T4: =iferror(MONTH(O4),"") -> 8 | U4: =iferror(YEAR(O4),"") -> 2024 | V4: =if(C4="","", IFERROR(DAY(C4),"")) -> 2 | W4: =if(C4="","",IFERROR(MONTH(C4),"")) -> 8 | X4: =if(C4="","",iferror(YEAR(C4),"")) -> 2024
A5: 45509 | C5: =IF(E5="pago",A5,"") -> 45509 | D5: Prefeitura Municipal De Indaiatuba | E5: Pago | F5: Boleto | G5: BANCO DO BRASIL - 65204-0 | H5: ALVARA MATRIZ | I5: 111.33 | K5: =if(E5="pago",(I5-J5),"") -> 111.33 | L5: Única | N5: ALVARÁ DE FUNCIONAMENTO | O5: =if(A5="","", TEXT(A5,"mm/yyyy")) -> 08/2024 | P5: =if(C5="","", TEXT(C5,"mm/yyyy")) -> 08/2024 | Q5: {=IFERROR(XLOOKUP(N5,'Classificação'!A:A,'Classificação'!B:B),"")} -> DESPESAS COM OCUPAÇÃO | R5: {=IFERROR(XLOOKUP(Q5,'Classificação'!B:B,'Classificação'!C:C),"")} -> DESPESAS FIXAS (-) | S5: =iferror(DAY(A5),"") -> 5 | T5: =iferror(MONTH(O5),"") -> 8 | U5: =iferror(YEAR(O5),"") -> 2024 | V5: =if(C5="","", IFERROR(DAY(C5),"")) -> 5 | W5: =if(C5="","",IFERROR(MONTH(C5),"")) -> 8 | X5: =if(C5="","",iferror(YEAR(C5),"")) -> 2024
A6: 45509 | C6: =IF(E6="pago",A6,"") -> 45509 | D6: Prefeitura Municipal De Indaiatuba | E6: Pago | F6: Boleto | G6: BANCO DO BRASIL - 65204-0 | H6: ALVARA MATRIZ | I6: 111.33 | K6: =if(E6="pago",(I6-J6),"") -> 111.33 | L6: Única | N6: ALVARÁ DE FUNCIONAMENTO | O6: =if(A6="","", TEXT(A6,"mm/yyyy")) -> 08/2024 | P6: =if(C6="","", TEXT(C6,"mm/yyyy")) -> 08/2024 | Q6: {=IFERROR(XLOOKUP(N6,'Classificação'!A:A,'Classificação'!B:B),"")} -> DESPESAS COM OCUPAÇÃO | R6: {=IFERROR(XLOOKUP(Q6,'Classificação'!B:B,'Classificação'!C:C),"")} -> DESPESAS FIXAS (-) | S6: =iferror(DAY(A6),"") -> 5 | T6: =iferror(MONTH(O6),"") -> 8 | U6: =iferror(YEAR(O6),"") -> 2024 | V6: =if(C6="","", IFERROR(DAY(C6),"")) -> 5 | W6: =if(C6="","",IFERROR(MONTH(C6),"")) -> 8 | X6: =if(C6="","",iferror(YEAR(C6),"")) -> 2024
A7: 45510 | C7: =IF(E7="pago",A7,"") -> 45510 | D7: LARISSA FARINCHON BORGES | E7: Pago | F7: Transferência bancária | G7: BANCO DO BRASIL - 65204-0 | I7: 2500 | K7: =if(E7="pago",(I7-J7),"") -> 2500 | L7: Mensal | N7: SALARIOS | O7: =if(A7="","", TEXT(A7,"mm/yyyy")) -> 08/2024 | P7: =if(C7="","", TEXT(C7,"mm/yyyy")) -> 08/2024 | Q7: {=IFERROR(XLOOKUP(N7,'Classificação'!A:A,'Classificação'!B:B),"")} -> DESPESAS COM PESSOAL | R7: {=IFERROR(XLOOKUP(Q7,'Classificação'!B:B,'Classificação'!C:C),"")} -> DESPESAS FIXAS (-) | S7: =iferror(DAY(A7),"") -> 6 | T7: =iferror(MONTH(O7),"") -> 8 | U7: =iferror(YEAR(O7),"") -> 2024 | V7: =if(C7="","", IFERROR(DAY(C7),"")) -> 6 | W7: =if(C7="","",IFERROR(MONTH(C7),"")) -> 8 | X7: =if(C7="","",iferror(YEAR(C7),"")) -> 2024
A8: 45510 | C8: =IF(E8="pago",A8,"") -> 45510 | D8: BANCO DO BRASIL | E8: Pago | F8: Pagamento automático | G8: BANCO DO BRASIL - 65204-0 | H8: CESTA DE TARIFAS | I8: 73.8 | K8: =if(E8="pago",(I8-J8),"") -> 73.8 | L8: Mensal | N8: TARIFAS BANCÁRIAS | O8: =if(A8="","", TEXT(A8,"mm/yyyy")) -> 08/2024 | P8: =if(C8="","", TEXT(C8,"mm/yyyy")) -> 08/2024 | Q8: {=IFERROR(XLOOKUP(N8,'Classificação'!A:A,'Classificação'!B:B),"")} -> DESPESAS NÃO OPERACIONAIS | R8: {=IFERROR(XLOOKUP(Q8,'Classificação'!B:B,'Classificação'!C:C),"")} -> RESULTADO NÃO OPERACIONAL (+/-) | S8: =iferror(DAY(A8),"") -> 6 | T8: =iferror(MONTH(O8),"") -> 8 | U8: =iferror(YEAR(O8),"") -> 2024 | V8: =if(C8="","", IFERROR(DAY(C8),"")) -> 6 | W8: =if(C8="","",IFERROR(MONTH(C8),"")) -> 8 | X8: =if(C8="","",iferror(YEAR(C8),"")) -> 2024
A9: 45516 | C9: 45516 | D9: AMIL ASSISTENCIA MEDICA INTERNACIONAL S.A. - CONVENIO MEDICO | E9: Pago | F9: Boleto | G9: BANCO DO BRASIL - 65204-0 | I9: 1375.64 | K9: =if(E9="pago",(I9-J9),"") -> 1375.64 | L9: Mensal | N9: CONVÊNIO MÉDICO | O9: =if(A9="","", TEXT(A9,"mm/yyyy")) -> 08/2024 | P9: =if(C9="","", TEXT(C9,"mm/yyyy")) -> 08/2024 | Q9: {=IFERROR(XLOOKUP(N9,'Classificação'!A:A,'Classificação'!B:B),"")} -> DESPESAS COM PESSOAL | R9: {=IFERROR(XLOOKUP(Q9,'Classificação'!B:B,'Classificação'!C:C),"")} -> DESPESAS FIXAS (-) | S9: =iferror(DAY(A9),"") -> 12 | T9: =iferror(MONTH(O9),"") -> 8 | U9: =iferror(YEAR(O9),"") -> 2024 | V9: =if(C9="","", IFERROR(DAY(C9),"")) -> 12 | W9: =if(C9="","",IFERROR(MONTH(C9),"")) -> 8 | X9: =if(C9="","",iferror(YEAR(C9),"")) -> 2024
A10: 45516 | C10: 45516 | D10: DESKTOP S A - INTERNET WIFI | E10: Pago | F10: Pix | G10: BANCO DO BRASIL - 65204-0 | I10: 139.99 | K10: =if(E10="pago",(I10-J10),"") -> 139.99 | L10: Mensal | N10: INTERNET | O10: =if(A10="","", TEXT(A10,"mm/yyyy")) -> 08/2024 | P10: =if(C10="","", TEXT(C10,"mm/yyyy")) -> 08/2024 | Q10: {=IFERROR(XLOOKUP(N10,'Classificação'!A:A,'Classificação'!B:B),"")} -> DESPESAS COM OCUPAÇÃO | R10: {=IFERROR(XLOOKUP(Q10,'Classificação'!B:B,'Classificação'!C:C),"")} -> DESPESAS FIXAS (-) | S10: =iferror(DAY(A10),"") -> 12 | T10: =iferror(MONTH(O10),"") -> 8 | U10: =iferror(YEAR(O10),"") -> 2024 | V10: =if(C10="","", IFERROR(DAY(C10),"")) -> 12 | W10: =if(C10="","",IFERROR(MONTH(C10),"")) -> 8 | X10: =if(C10="","",iferror(YEAR(C10),"")) -> 2024
A11: 45516 | C11: 45516 | D11: BANCO DO BRASIL | E11: Pago | F11: Pagamento automático | G11: BANCO DO BRASIL - 65204-0 | H11: CONSORCIO | I11: 458.5 | K11: =if(E11="pago",(I11-J11),"") -> 458.5 | L11: Parcelado | M11: 9/48 | N11: PARCELA DO FINANCIAMENTO | O11: =if(A11="","", TEXT(A11,"mm/yyyy")) -> 08/2024 | P11: =if(C11="","", TEXT(C11,"mm/yyyy")) -> 08/2024 | Q11: {=IFERROR(XLOOKUP(N11,'Classificação'!A:A,'Classificação'!B:B),"")} -> DESPESAS NÃO OPERACIONAIS | R11: {=IFERROR(XLOOKUP(Q11,'Classificação'!B:B,'Classificação'!C:C),"")} -> RESULTADO NÃO OPERACIONAL (+/-) | S11: =iferror(DAY(A11),"") -> 12 | T11: =iferror(MONTH(O11),"") -> 8 | U11: =iferror(YEAR(O11),"") -> 2024 | V11: =if(C11="","", IFERROR(DAY(C11),"")) -> 12 | W11: =if(C11="","",IFERROR(MONTH(C11),"")) -> 8 | X11: =if(C11="","",iferror(YEAR(C11),"")) -> 2024
A12: 45516 | C12: 45516 | D12: CELIO LUIZ DE LIMA - VIGIA DA RUA | E12: Pago | F12: Pix | G12: MERCADO PAGO SINCE - 9511092439-1 | H12: VIGILANTE DA RUA | I12: 50 | K12: =if(E12="pago",(I12-J12),"") -> 50 | L12: Mensal | N12: SERVIÇOS TERCEIRIZADOS | O12: =if(A12="","", TEXT(A12,"mm/yyyy")) -> 08/2024 | P12: =if(C12="","", TEXT(C12,"mm/yyyy")) -> 08/2024 | Q12: {=IFERROR(XLOOKUP(N12,'Classificação'!A:A,'Classificação'!B:B),"")} -> DESPESAS ADMINISTRATIVAS | R12: {=IFERROR(XLOOKUP(Q12,'Classificação'!B:B,'Classificação'!C:C),"")} -> DESPESAS FIXAS (-) | S12: =iferror(DAY(A12),"") -> 12 | T12: =iferror(MONTH(O12),"") -> 8 | U12: =iferror(YEAR(O12),"") -> 2024 | V12: =if(C12="","", IFERROR(DAY(C12),"")) -> 12 | W12: =if(C12="","",IFERROR(MONTH(C12),"")) -> 8 | X12: =if(C12="","",iferror(YEAR(C12),"")) -> 2024
A13: 45516 | C13: 45516 | D13: Sidecont Contabilidade E Consultoria | E13: Pago | F13: Boleto | G13: MERCADO PAGO SINCE - 9511092439-1 | H13: CONTABILIDADE DA SINCE | I13: 397 | K13: =if(E13="pago",(I13-J13),"") -> 397 | L13: Mensal | N13: CONTABILIDADE | O13: =if(A13="","", TEXT(A13,"mm/yyyy")) -> 08/2024 | P13: =if(C13="","", TEXT(C13,"mm/yyyy")) -> 08/2024 | Q13: {=IFERROR(XLOOKUP(N13,'Classificação'!A:A,'Classificação'!B:B),"")} -> DESPESAS ADMINISTRATIVAS | R13: {=IFERROR(XLOOKUP(Q13,'Classificação'!B:B,'Classificação'!C:C),"")} -> DESPESAS FIXAS (-) | S13: =iferror(DAY(A13),"") -> 12 | T13: =iferror(MONTH(O13),"") -> 8 | U13: =iferror(YEAR(O13),"") -> 2024 | V13: =if(C13="","", IFERROR(DAY(C13),"")) -> 12 | W13: =if(C13="","",IFERROR(MONTH(C13),"")) -> 8 | X13: =if(C13="","",iferror(YEAR(C13),"")) -> 2024
A14: 45516 | B14: 45516 | C14: =IF(E14="pago",A14,"") -> 45516 | D14: MEDPREVENT EXAME ADMISSIONAL | E14: Pago | F14: Pix | G14: BANCO DO BRASIL - 65204-0 | H14: EXAME ADMISSIONAL ADRIANE | I14: 65 | K14: =if(E14="pago",(I14-J14),"") -> 65 | L14: Única | N14: OUTRAS DESPESAS COM PESSOAL | O14: =if(A14="","", TEXT(A14,"mm/yyyy")) -> 08/2024 | P14: =if(C14="","", TEXT(C14,"mm/yyyy")) -> 08/2024 | Q14: {=IFERROR(XLOOKUP(N14,'Classificação'!A:A,'Classificação'!B:B),"")} -> DESPESAS COM PESSOAL | R14: {=IFERROR(XLOOKUP(Q14,'Classificação'!B:B,'Classificação'!C:C),"")} -> DESPESAS FIXAS (-) | S14: =iferror(DAY(A14),"") -> 12 | T14: =iferror(MONTH(O14),"") -> 8 | U14: =iferror(YEAR(O14),"") -> 2024 | V14: =if(C14="","", IFERROR(DAY(C14),"")) -> 12 | W14: =if(C14="","",IFERROR(MONTH(C14),"")) -> 8 | X14: =if(C14="","",iferror(YEAR(C14),"")) -> 2024
A15: 45516 | C15: =IF(E15="pago",A15,"") -> 45516 | D15: ELAINE CRISTINA DE MELO | E15: Pago | F15: Transferência bancária | G15: BANCO DO BRASIL - 65204-0 | I15: 1000 | K15: =if(E15="pago",(I15-J15),"") -> 1000 | L15: Mensal | N15: SALARIOS | O15: =if(A15="","", TEXT(A15,"mm/yyyy")) -> 08/2024 | P15: =if(C15="","", TEXT(C15,"mm/yyyy")) -> 08/2024 | Q15: {=IFERROR(XLOOKUP(N15,'Classificação'!A:A,'Classificação'!B:B),"")} -> DESPESAS COM PESSOAL | R15: {=IFERROR(XLOOKUP(Q15,'Classificação'!B:B,'Classificação'!C:C),"")} -> DESPESAS FIXAS (-) | S15: =iferror(DAY(A15),"") -> 12 | T15: =iferror(MONTH(O15),"") -> 8 | U15: =iferror(YEAR(O15),"") -> 2024 | V15: =if(C15="","", IFERROR(DAY(C15),"")) -> 12 | W15: =if(C15="","",IFERROR(MONTH(C15),"")) -> 8 | X15: =if(C15="","",iferror(YEAR(C15),"")) -> 2024
A16: 45516 | C16: =IF(E16="pago",A16,"") -> 45516 | D16: LARISSA FARINCHON BORGES | E16: Pago | F16: Transferência bancária | G16: BANCO DO BRASIL - 65204-0 | I16: 2500 | K16: =if(E16="pago",(I16-J16),"") -> 2500 | L16: Única | N16: SALARIOS | O16: =if(A16="","", TEXT(A16,"mm/yyyy")) -> 08/2024 | P16: =if(C16="","", TEXT(C16,"mm/yyyy")) -> 08/2024 | Q16: {=IFERROR(XLOOKUP(N16,'Classificação'!A:A,'Classificação'!B:B),"")} -> DESPESAS COM PESSOAL | R16: {=IFERROR(XLOOKUP(Q16,'Classificação'!B:B,'Classificação'!C:C),"")} -> DESPESAS FIXAS (-) | S16: =iferror(DAY(A16),"") -> 12 | T16: =iferror(MONTH(O16),"") -> 8 | U16: =iferror(YEAR(O16),"") -> 2024 | V16: =if(C16="","", IFERROR(DAY(C16),"")) -> 12 | W16: =if(C16="","",IFERROR(MONTH(C16),"")) -> 8 | X16: =if(C16="","",iferror(YEAR(C16),"")) -> 2024
A17: 45517 | C17: =IF(E17="pago",A17,"") -> 45517 | D17: MERCADO LIVRE | E17: Pago | F17: Pagamento automático | G17: MERCADO PAGO FARMEL - | H17: CUSTO DO FULL FARMEL (COLETA E ARMAZENAGEM) | I17: 1010.16 | K17: =if(E17="pago",(I17-J17),"") -> 1010.16 | L17: Mensal | N17: FRETE DE VENDAS | O17: =if(A17="","", TEXT(A17,"mm/yyyy")) -> 08/2024 | P17: =if(C17="","", TEXT(C17,"mm/yyyy")) -> 08/2024 | Q17: {=IFERROR(XLOOKUP(N17,'Classificação'!A:A,'Classificação'!B:B),"")} -> FRETE DE VENDAS | R17: {=IFERROR(XLOOKUP(Q17,'Classificação'!B:B,'Classificação'!C:C),"")} -> CUSTOS VARIÁVEIS | S17: =iferror(DAY(A17),"") -> 13 | T17: =iferror(MONTH(O17),"") -> 8 | U17: =iferror(YEAR(O17),"") -> 2024 | V17: =if(C17="","", IFERROR(DAY(C17),"")) -> 13 | W17: =if(C17="","",IFERROR(MONTH(C17),"")) -> 8 | X17: =if(C17="","",iferror(YEAR(C17),"")) -> 2024
A18: 45517 | C18: =IF(E18="pago",A18,"") -> 45517 | D18: TAKATA TAKATA COMERCIO DE DOCES E SALGADOS | E18: Pago | F18: Pix | G18: MERCADO PAGO SINCE - 9511092439-1 | H18: BOLO NIVER ELAINE | I18: 90 | K18: =if(E18="pago",(I18-J18),"") -> 90 | L18: Única | N18: COMPRA DE MERCADO/PADARIA | O18: =if(A18="","", TEXT(A18,"mm/yyyy")) -> 08/2024 | Q18: {=IFERROR(XLOOKUP(N18,'Classificação'!A:A,'Classificação'!B:B),"")} -> DESPESAS DIVERSAS | R18: {=IFERROR(XLOOKUP(Q18,'Classificação'!B:B,'Classificação'!C:C),"")} -> DESPESAS FIXAS (-) | S18: =iferror(DAY(A18),"") -> 13 | T18: =iferror(MONTH(O18),"") -> 8 | U18: =iferror(YEAR(O18),"") -> 2024 | V18: =if(C18="","", IFERROR(DAY(C18),"")) -> 13 | W18: =if(C18="","",IFERROR(MONTH(C18),"")) -> 8 | X18: =if(C18="","",iferror(YEAR(C18),"")) -> 2024
A19: 45518 | C19: =IF(E19="pago",A19,"") -> 45518 | D19: BANCO DO BRASIL | E19: Pago | F19: Pagamento automático | G19: BANCO DO BRASIL - 65204-0 | H19: CAPITAL DE GIRO PEAC FGI JUROS | I19: 2786.78 | K19: =if(E19="pago",(I19-J19),"") -> 2786.78 | L19: Parcelado | M19: 45445 | N19: PAGAMENTO DE EMPRESTIMOS (BANCOS) | O19: =if(A19="","", TEXT(A19,"mm/yyyy")) -> 08/2024 | P19: =if(C19="","", TEXT(C19,"mm/yyyy")) -> 08/2024 | Q19: {=IFERROR(XLOOKUP(N19,'Classificação'!A:A,'Classificação'!B:B),"")} -> DESPESAS NÃO OPERACIONAIS | R19: {=IFERROR(XLOOKUP(Q19,'Classificação'!B:B,'Classificação'!C:C),"")} -> RESULTADO NÃO OPERACIONAL (+/-) | S19: =iferror(DAY(A19),"") -> 14 | T19: =iferror(MONTH(O19),"") -> 8 | U19: =iferror(YEAR(O19),"") -> 2024 | V19: =if(C19="","", IFERROR(DAY(C19),"")) -> 14 | W19: =if(C19="","",IFERROR(MONTH(C19),"")) -> 8 | X19: =if(C19="","",iferror(YEAR(C19),"")) -> 2024
A20: 45519 | C20: =IF(E20="pago",A20,"") -> 45519 | D20: ADRIANE CRISTINA GOMES | E20: Pago | F20: Pix | G20: MERCADO PAGO SINCE - 9511092439-1 | I20: 592 | K20: =if(E20="pago",(I20-J20),"") -> 592 | L20: Mensal | N20: ADIANTAMENTO DE SALARIO | O20: =if(A20="","", TEXT(A20,"mm/yyyy")) -> 08/2024 | P20: =if(C20="","", TEXT(C20,"mm/yyyy")) -> 08/2024 | Q20: {=IFERROR(XLOOKUP(N20,'Classificação'!A:A,'Classificação'!B:B),"")} -> DESPESAS COM PESSOAL | R20: {=IFERROR(XLOOKUP(Q20,'Classificação'!B:B,'Classificação'!C:C),"")} -> DESPESAS FIXAS (-) | S20: =iferror(DAY(A20),"") -> 15 | T20: =iferror(MONTH(O20),"") -> 8 | U20: =iferror(YEAR(O20),"") -> 2024 | V20: =if(C20="","", IFERROR(DAY(C20),"")) -> 15 | W20: =if(C20="","",IFERROR(MONTH(C20),"")) -> 8 | X20: =if(C20="","",iferror(YEAR(C20),"")) -> 2024
A21: 45519 | C21: =IF(E21="pago",A21,"") -> 45519 | D21: William Bezerra de Melo | E21: Pago | F21: Transferência bancária | G21: BANCO DO BRASIL - 65204-0 | H21: COMPRA DE BOLO - REEMBOLSO WILLIAM | I21: 24 | K21: =if(E21="pago",(I21-J21),"") -> 24 | L21: Única | N21: ALIMENTAÇÃO FUNCIONARIOS | O21: =if(A21="","", TEXT(A21,"mm/yyyy")) -> 08/2024 | P21: =if(C21="","", TEXT(C21,"mm/yyyy")) -> 08/2024 | Q21: {=IFERROR(XLOOKUP(N21,'Classificação'!A:A,'Classificação'!B:B),"")} -> DESPESAS COM PESSOAL | R21: {=IFERROR(XLOOKUP(Q21,'Classificação'!B:B,'Classificação'!C:C),"")} -> DESPESAS FIXAS (-) | S21: =iferror(DAY(A21),"") -> 15 | T21: =iferror(MONTH(O21),"") -> 8 | U21: =iferror(YEAR(O21),"") -> 2024 | V21: =if(C21="","", IFERROR(DAY(C21),"")) -> 15 | W21: =if(C21="","",IFERROR(MONTH(C21),"")) -> 8 | X21: =if(C21="","",iferror(YEAR(C21),"")) -> 2024
A22: 45519 | C22: =IF(E22="pago",A22,"") -> 45519 | D22: Debora Morales de Melo | E22: Pago | F22: Pix | G22: MERCADO PAGO SINCE - 9511092439-1 | I22: 750 | K22: =if(E22="pago",(I22-J22),"") -> 750 | L22: Mensal | N22: SALARIOS | O22: =if(A22="","", TEXT(A22,"mm/yyyy")) -> 08/2024 | P22: =if(C22="","", TEXT(C22,"mm/yyyy")) -> 08/2024 | Q22: {=IFERROR(XLOOKUP(N22,'Classificação'!A:A,'Classificação'!B:B),"")} -> DESPESAS COM PESSOAL | R22: {=IFERROR(XLOOKUP(Q22,'Classificação'!B:B,'Classificação'!C:C),"")} -> DESPESAS FIXAS (-) | S22: =iferror(DAY(A22),"") -> 15 | T22: =iferror(MONTH(O22),"") -> 8 | U22: =iferror(YEAR(O22),"") -> 2024 | V22: =if(C22="","", IFERROR(DAY(C22),"")) -> 15 | W22: =if(C22="","",IFERROR(MONTH(C22),"")) -> 8 | X22: =if(C22="","",iferror(YEAR(C22),"")) -> 2024
A23: 45519 | C23: =IF(E23="pago",A23,"") -> 45519 | D23: Priscila Zaghi Da Silva | E23: Pago | F23: Transferência bancária | G23: BANCO DO BRASIL - 65204-0 | I23: 720 | K23: =if(E23="pago",(I23-J23),"") -> 720 | L23: Mensal | N23: ADIANTAMENTO DE SALARIO | O23: =if(A23="","", TEXT(A23,"mm/yyyy")) -> 08/2024 | P23: =if(C23="","", TEXT(C23,"mm/yyyy")) -> 08/2024 | Q23: {=IFERROR(XLOOKUP(N23,'Classificação'!A:A,'Classificação'!B:B),"")} -> DESPESAS COM PESSOAL | R23: {=IFERROR(XLOOKUP(Q23,'Classificação'!B:B,'Classificação'!C:C),"")} -> DESPESAS FIXAS (-) | S23: =iferror(DAY(A23),"") -> 15 | T23: =iferror(MONTH(O23),"") -> 8 | U23: =iferror(YEAR(O23),"") -> 2024 | V23: =if(C23="","", IFERROR(DAY(C23),"")) -> 15 | W23: =if(C23="","",IFERROR(MONTH(C23),"")) -> 8 | X23: =if(C23="","",iferror(YEAR(C23),"")) -> 2024
A24: 45519 | C24: =IF(E24="pago",A24,"") -> 45519 | D24: Sumerbol Supermercados Ltda | E24: Pago | F24: Pix | G24: MERCADO PAGO SINCE - 9511092439-1 | H24: CAFÉ - REEMBOLSO WILLIAM | I24: 20.99 | K24: =if(E24="pago",(I24-J24),"") -> 20.99 | L24: Única | N24: COMPRA DE MERCADO/PADARIA | O24: =if(A24="","", TEXT(A24,"mm/yyyy")) -> 08/2024 | P24: =if(C24="","", TEXT(C24,"mm/yyyy")) -> 08/2024 | Q24: {=IFERROR(XLOOKUP(N24,'Classificação'!A:A,'Classificação'!B:B),"")} -> DESPESAS DIVERSAS | R24: {=IFERROR(XLOOKUP(Q24,'Classificação'!B:B,'Classificação'!C:C),"")} -> DESPESAS FIXAS (-) | S24: =iferror(DAY(A24),"") -> 15 | T24: =iferror(MONTH(O24),"") -> 8 | U24: =iferror(YEAR(O24),"") -> 2024 | V24: =if(C24="","", IFERROR(DAY(C24),"")) -> 15 | W24: =if(C24="","",IFERROR(MONTH(C24),"")) -> 8 | X24: =if(C24="","",iferror(YEAR(C24),"")) -> 2024
A25: 45519 | C25: =IF(E25="pago",A25,"") -> 45519 | D25: THIAGO MAURICIO BERTI | E25: Pago | F25: Transferência bancária | G25: BANCO DO BRASIL - 65204-0 | I25: 744 | K25: =if(E25="pago",(I25-J25),"") -> 744 | L25: Mensal | N25: ADIANTAMENTO DE SALARIO | O25: =if(A25="","", TEXT(A25,"mm/yyyy")) -> 08/2024 | P25: =if(C25="","", TEXT(C25,"mm/yyyy")) -> 08/2024 | Q25: {=IFERROR(XLOOKUP(N25,'Classificação'!A:A,'Classificação'!B:B),"")} -> DESPESAS COM PESSOAL | R25: {=IFERROR(XLOOKUP(Q25,'Classificação'!B:B,'Classificação'!C:C),"")} -> DESPESAS FIXAS (-) | S25: =iferror(DAY(A25),"") -> 15 | T25: =iferror(MONTH(O25),"") -> 8 | U25: =iferror(YEAR(O25),"") -> 2024 | V25: =if(C25="","", IFERROR(DAY(C25),"")) -> 15 | W25: =if(C25="","",IFERROR(MONTH(C25),"")) -> 8 | X25: =if(C25="","",iferror(YEAR(C25),"")) -> 2024
A26: 45519 | C26: =IF(E26="pago",A26,"") -> 45519 | D26: William Bezerra de Melo | E26: Pago | F26: Pix | G26: BANCO DO BRASIL - 65204-0 | H26: Empréstimo para importação - QUANTUM a ser pago para William, pix: CPF04767793408 | I26: 2500 | K26: =if(E26="pago",(I26-J26),"") -> 2500 | L26: Parcelado | M26: 45512 | N26: EMPRESTIMOS PARA TERCEIROS | O26: =if(A26="","", TEXT(A26,"mm/yyyy")) -> 08/2024 | P26: =if(C26="","", TEXT(C26,"mm/yyyy")) -> 08/2024 | Q26: {=IFERROR(XLOOKUP(N26,'Classificação'!A:A,'Classificação'!B:B),"")} -> DESPESAS NÃO OPERACIONAIS | R26: {=IFERROR(XLOOKUP(Q26,'Classificação'!B:B,'Classificação'!C:C),"")} -> RESULTADO NÃO OPERACIONAL (+/-) | S26: =iferror(DAY(A26),"") -> 15 | T26: =iferror(MONTH(O26),"") -> 8 | U26: =iferror(YEAR(O26),"") -> 2024 | V26: =if(C26="","", IFERROR(DAY(C26),"")) -> 15 | W26: =if(C26="","",IFERROR(MONTH(C26),"")) -> 8 | X26: =if(C26="","",iferror(YEAR(C26),"")) -> 2024
A27: 45520 | C27: =IF(E27="pago",A27,"") -> 45520 | D27: Regina Celia Moura de Oliveira - Barbara Bolsas | E27: Pago | F27: Cheque | G27: BANCO DO BRASIL - 65204-0 | H27: PEDIDO DE COMPRA 318 CHEQUE 850030 | I27: 1127.5 | K27: =if(E27="pago",(I27-J27),"") -> 1127.5 | L27: Parcelado | M27: 45352 | N27: COMPRA DE MERCADORIA | O27: =if(A27="","", TEXT(A27,"mm/yyyy")) -> 08/2024 | P27: =if(C27="","", TEXT(C27,"mm/yyyy")) -> 08/2024 | Q27: {=IFERROR(XLOOKUP(N27,'Classificação'!A:A,'Classificação'!B:B),"")} -> COMPRA DE MERCADORIA | R27: {=IFERROR(XLOOKUP(Q27,'Classificação'!B:B,'Classificação'!C:C),"")} -> CUSTOS VARIÁVEIS | S27: =iferror(DAY(A27),"") -> 16 | T27: =iferror(MONTH(O27),"") -> 8 | U27: =iferror(YEAR(O27),"") -> 2024 | V27: =if(C27="","", IFERROR(DAY(C27),"")) -> 16 | W27: =if(C27="","",IFERROR(MONTH(C27),"")) -> 8 | X27: =if(C27="","",iferror(YEAR(C27),"")) -> 2024
A28: 45520 | C28: =IF(E28="pago",A28,"") -> 45520 | D28: Regina Celia Moura de Oliveira - Barbara Bolsas | E28: Pago | F28: Cheque | G28: BANCO DO BRASIL - 65204-0 | H28: PEDIDO DE COMPRA 313 CHEQUE 850025 | I28: 1533 | K28: =if(E28="pago",(I28-J28),"") -> 1533 | L28: Parcelado | M28: 45323 | N28: COMPRA DE MERCADORIA | O28: =if(A28="","", TEXT(A28,"mm/yyyy")) -> 08/2024 | P28: =if(C28="","", TEXT(C28,"mm/yyyy")) -> 08/2024 | Q28: {=IFERROR(XLOOKUP(N28,'Classificação'!A:A,'Classificação'!B:B),"")} -> COMPRA DE MERCADORIA | R28: {=IFERROR(XLOOKUP(Q28,'Classificação'!B:B,'Classificação'!C:C),"")} -> CUSTOS VARIÁVEIS | S28: =iferror(DAY(A28),"") -> 16 | T28: =iferror(MONTH(O28),"") -> 8 | U28: =iferror(YEAR(O28),"") -> 2024 | V28: =if(C28="","", IFERROR(DAY(C28),"")) -> 16 | W28: =if(C28="","",IFERROR(MONTH(C28),"")) -> 8 | X28: =if(C28="","",iferror(YEAR(C28),"")) -> 2024
A29: 45520 | C29: =IF(E29="pago",A29,"") -> 45520 | D29: CPFL - COMPAHIA DE FORÇA E LUZ | E29: Pago | F29: Boleto | G29: BANCO DO BRASIL - 65204-0 | H29: PROVISIONAMENTO CPFL | I29: 374.8 | K29: =if(E29="pago",(I29-J29),"") -> 374.8 | L29: Mensal | N29: ENERGIA ELETRICA | O29: =if(A29="","", TEXT(A29,"mm/yyyy")) -> 08/2024 | P29: =if(C29="","", TEXT(C29,"mm/yyyy")) -> 08/2024 | Q29: {=IFERROR(XLOOKUP(N29,'Classificação'!A:A,'Classificação'!B:B),"")} -> DESPESAS COM OCUPAÇÃO | R29: {=IFERROR(XLOOKUP(Q29,'Classificação'!B:B,'Classificação'!C:C),"")} -> DESPESAS FIXAS (-) | S29: =iferror(DAY(A29),"") -> 16 | T29: =iferror(MONTH(O29),"") -> 8 | U29: =iferror(YEAR(O29),"") -> 2024 | V29: =if(C29="","", IFERROR(DAY(C29),"")) -> 16 | W29: =if(C29="","",IFERROR(MONTH(C29),"")) -> 8 | X29: =if(C29="","",iferror(YEAR(C29),"")) -> 2024
A30: 45520 | B30: 45520 | C30: =IF(E30="pago",A30,"") -> 45520 | D30: PONTO AZUL | E30: Pago | F30: Pix | G30: MERCADO PAGO SINCE - 9511092439-1 | H30: CABO PARA NOTEBOOK | I30: 20 | K30: =if(E30="pago",(I30-J30),"") -> 20 | L30: Única | N30: COMPRA DE BENS/EQUIPAMENTOS | O30: =if(A30="","", TEXT(A30,"mm/yyyy")) -> 08/2024 | Q30: {=IFERROR(XLOOKUP(N30,'Classificação'!A:A,'Classificação'!B:B),"")} -> DESPESAS NÃO OPERACIONAIS | R30: {=IFERROR(XLOOKUP(Q30,'Classificação'!B:B,'Classificação'!C:C),"")} -> RESULTADO NÃO OPERACIONAL (+/-) | S30: =iferror(DAY(A30),"") -> 16 | T30: =iferror(MONTH(O30),"") -> 8 | U30: =iferror(YEAR(O30),"") -> 2024 | V30: =if(C30="","", IFERROR(DAY(C30),"")) -> 16 | W30: =if(C30="","",IFERROR(MONTH(C30),"")) -> 8 | X30: =if(C30="","",iferror(YEAR(C30),"")) -> 2024
A31: 45520 | C31: =IF(E31="pago",A31,"") -> 45520 | D31: BANCO DO BRASIL | E31: Pago | F31: Pagamento automático | G31: BANCO DO BRASIL - 65204-0 | H31: Tarifa Agrupada | I31: 7.36 | K31: =if(E31="pago",(I31-J31),"") -> 7.36 | L31: Única | N31: TARIFAS DE PIX | O31: =if(A31="","", TEXT(A31,"mm/yyyy")) -> 08/2024 | Q31: {=IFERROR(XLOOKUP(N31,'Classificação'!A:A,'Classificação'!B:B),"")} -> TARIFAS DE PIX | R31: {=IFERROR(XLOOKUP(Q31,'Classificação'!B:B,'Classificação'!C:C),"")} -> (+/-) RESULTADO FINANCEIRO LÍQUIDO | S31: =iferror(DAY(A31),"") -> 16 | T31: =iferror(MONTH(O31),"") -> 8 | U31: =iferror(YEAR(O31),"") -> 2024 | V31: =if(C31="","", IFERROR(DAY(C31),"")) -> 16 | W31: =if(C31="","",IFERROR(MONTH(C31),"")) -> 8 | X31: =if(C31="","",iferror(YEAR(C31),"")) -> 2024
A32: 45523 | C32: =IF(E32="pago",A32,"") -> 45523 | D32: BANCO DO BRASIL | E32: Pago | F32: Pagamento automático | G32: BANCO DO BRASIL - 65204-0 | H32: PRONAMPE 1º CONTRATO | I32: 3511.72 | K32: =if(E32="pago",(I32-J32),"") -> 3511.72 | L32: Parcelado | M32: 2/48 | N32: PAGAMENTO DE EMPRESTIMOS (BANCOS) | O32: =if(A32="","", TEXT(A32,"mm/yyyy")) -> 08/2024 | P32: =if(C32="","", TEXT(C32,"mm/yyyy")) -> 08/2024 | Q32: {=IFERROR(XLOOKUP(N32,'Classificação'!A:A,'Classificação'!B:B),"")} -> DESPESAS NÃO OPERACIONAIS | R32: {=IFERROR(XLOOKUP(Q32,'Classificação'!B:B,'Classificação'!C:C),"")} -> RESULTADO NÃO OPERACIONAL (+/-) | S32: =iferror(DAY(A32),"") -> 19 | T32: =iferror(MONTH(O32),"") -> 8 | U32: =iferror(YEAR(O32),"") -> 2024 | V32: =if(C32="","", IFERROR(DAY(C32),"")) -> 19 | W32: =if(C32="","",IFERROR(MONTH(C32),"")) -> 8 | X32: =if(C32="","",iferror(YEAR(C32),"")) -> 2024
A33: 45523 | C33: =IF(E33="pago",A33,"") -> 45523 | D33: DAS - SIMPLES NACIONAL | E33: Pago | F33: Boleto | G33: MERCADO PAGO SINCE - 9511092439-1 | I33: 78.93 | K33: =if(E33="pago",(I33-J33),"") -> 78.93 | L33: Mensal | N33: IMPOSTO DE RENDA - DAS | O33: =if(A33="","", TEXT(A33,"mm/yyyy")) -> 08/2024 | P33: =if(C33="","", TEXT(C33,"mm/yyyy")) -> 08/2024 | Q33: {=IFERROR(XLOOKUP(N33,'Classificação'!A:A,'Classificação'!B:B),"")} -> IMPOSTO DE RENDA - DAS | R33: {=IFERROR(XLOOKUP(Q33,'Classificação'!B:B,'Classificação'!C:C),"")} -> DEDUÇÕES DA RECEITA BRUTA (-) | S33: =iferror(DAY(A33),"") -> 19 | T33: =iferror(MONTH(O33),"") -> 8 | U33: =iferror(YEAR(O33),"") -> 2024 | V33: =if(C33="","", IFERROR(DAY(C33),"")) -> 19 | W33: =if(C33="","",IFERROR(MONTH(C33),"")) -> 8 | X33: =if(C33="","",iferror(YEAR(C33),"")) -> 2024
A34: 45523 | C34: =IF(E34="pago",A34,"") -> 45523 | D34: ELAINE CRISTINA DE MELO | E34: Pago | F34: Transferência bancária | G34: MERCADO PAGO SINCE - 9511092439-1 | I34: 3250 | K34: =if(E34="pago",(I34-J34),"") -> 3250 | L34: Mensal | N34: SALARIOS | O34: =if(A34="","", TEXT(A34,"mm/yyyy")) -> 08/2024 | P34: =if(C34="","", TEXT(C34,"mm/yyyy")) -> 08/2024 | Q34: {=IFERROR(XLOOKUP(N34,'Classificação'!A:A,'Classificação'!B:B),"")} -> DESPESAS COM PESSOAL | R34: {=IFERROR(XLOOKUP(Q34,'Classificação'!B:B,'Classificação'!C:C),"")} -> DESPESAS FIXAS (-) | S34: =iferror(DAY(A34),"") -> 19 | T34: =iferror(MONTH(O34),"") -> 8 | U34: =iferror(YEAR(O34),"") -> 2024 | V34: =if(C34="","", IFERROR(DAY(C34),"")) -> 19 | W34: =if(C34="","",IFERROR(MONTH(C34),"")) -> 8 | X34: =if(C34="","",iferror(YEAR(C34),"")) -> 2024
A35: 45523 | C35: =IF(E35="pago",A35,"") -> 45523 | D35: LARISSA FARINCHON BORGES | E35: Pago | F35: Transferência bancária | G35: MERCADO PAGO SINCE - 9511092439-1 | I35: 3250 | K35: =if(E35="pago",(I35-J35),"") -> 3250 | L35: Mensal | N35: SALARIOS | O35: =if(A35="","", TEXT(A35,"mm/yyyy")) -> 08/2024 | P35: =if(C35="","", TEXT(C35,"mm/yyyy")) -> 08/2024 | Q35: {=IFERROR(XLOOKUP(N35,'Classificação'!A:A,'Classificação'!B:B),"")} -> DESPESAS COM PESSOAL | R35: {=IFERROR(XLOOKUP(Q35,'Classificação'!B:B,'Classificação'!C:C),"")} -> DESPESAS FIXAS (-) | S35: =iferror(DAY(A35),"") -> 19 | T35: =iferror(MONTH(O35),"") -> 8 | U35: =iferror(YEAR(O35),"") -> 2024 | V35: =if(C35="","", IFERROR(DAY(C35),"")) -> 19 | W35: =if(C35="","",IFERROR(MONTH(C35),"")) -> 8 | X35: =if(C35="","",iferror(YEAR(C35),"")) -> 2024
A36: 45524 | C36: =IF(E36="pago",A36,"") -> 45524 | D36: Jose Alberto | E36: Pago | F36: Pix | G36: MERCADO PAGO SINCE - 9511092439-1 | I36: 500 | K36: =if(E36="pago",(I36-J36),"") -> 500 | L36: Única | N36: SERVIÇOS TERCEIRIZADOS | O36: =if(A36="","", TEXT(A36,"mm/yyyy")) -> 08/2024 | P36: =if(C36="","", TEXT(C36,"mm/yyyy")) -> 08/2024 | Q36: {=IFERROR(XLOOKUP(N36,'Classificação'!A:A,'Classificação'!B:B),"")} -> DESPESAS ADMINISTRATIVAS | R36: {=IFERROR(XLOOKUP(Q36,'Classificação'!B:B,'Classificação'!C:C),"")} -> DESPESAS FIXAS (-) | S36: =iferror(DAY(A36),"") -> 20 | T36: =iferror(MONTH(O36),"") -> 8 | U36: =iferror(YEAR(O36),"") -> 2024 | V36: =if(C36="","", IFERROR(DAY(C36),"")) -> 20 | W36: =if(C36="","",IFERROR(MONTH(C36),"")) -> 8 | X36: =if(C36="","",iferror(YEAR(C36),"")) -> 2024
A37: 45524 | C37: =IF(E37="pago",A37,"") -> 45524 | D37: MERCADO LIVRE | E37: Pago | F37: Pagamento automático | G37: MERCADO PAGO SINCE - 9511092439-1 | H37: CUSTO DO FULL SINCE(COLETA E ARMAZENAGEM) | I37: 826.14 | K37: =if(E37="pago",(I37-J37),"") -> 826.14 | L37: Mensal | N37: FRETE DE VENDAS | O37: =if(A37="","", TEXT(A37,"mm/yyyy")) -> 08/2024 | P37: =if(C37="","", TEXT(C37,"mm/yyyy")) -> 08/2024 | Q37: {=IFERROR(XLOOKUP(N37,'Classificação'!A:A,'Classificação'!B:B),"")} -> FRETE DE VENDAS | R37: {=IFERROR(XLOOKUP(Q37,'Classificação'!B:B,'Classificação'!C:C),"")} -> CUSTOS VARIÁVEIS | S37: =iferror(DAY(A37),"") -> 20 | T37: =iferror(MONTH(O37),"") -> 8 | U37: =iferror(YEAR(O37),"") -> 2024 | V37: =if(C37="","", IFERROR(DAY(C37),"")) -> 20 | W37: =if(C37="","",IFERROR(MONTH(C37),"")) -> 8 | X37: =if(C37="","",iferror(YEAR(C37),"")) -> 2024
A38: 45524 | C38: =IF(E38="pago",A38,"") -> 45524 | D38: BLING SISTEMA ERP | E38: Pago | F38: Boleto | G38: BANCO DO BRASIL - 65204-0 | I38: 400 | K38: =if(E38="pago",(I38-J38),"") -> 400 | L38: Mensal | N38: DESPESA COM SISTEMAS | O38: =if(A38="","", TEXT(A38,"mm/yyyy")) -> 08/2024 | P38: =if(C38="","", TEXT(C38,"mm/yyyy")) -> 08/2024 | Q38: {=IFERROR(XLOOKUP(N38,'Classificação'!A:A,'Classificação'!B:B),"")} -> DESPESAS ADMINISTRATIVAS | R38: {=IFERROR(XLOOKUP(Q38,'Classificação'!B:B,'Classificação'!C:C),"")} -> DESPESAS FIXAS (-) | S38: =iferror(DAY(A38),"") -> 20 | T38: =iferror(MONTH(O38),"") -> 8 | U38: =iferror(YEAR(O38),"") -> 2024 | V38: =if(C38="","", IFERROR(DAY(C38),"")) -> 20 | W38: =if(C38="","",IFERROR(MONTH(C38),"")) -> 8 | X38: =if(C38="","",iferror(YEAR(C38),"")) -> 2024
A39: 45524 | B39: 45458 | C39: =IF(E39="pago",A39,"") -> 45524 | D39: BRASTEMP | E39: Pago | F39: Cartão de Crédito ELO | G39: BANCO DO BRASIL - 65204-0 | H39: CARTÃO ELO - FRIGOBAR | I39: 278.01 | K39: =if(E39="pago",(I39-J39),"") -> 278.01 | L39: Parcelado | M39: 45474 | N39: COMPRA DE BENS/EQUIPAMENTOS | O39: =if(A39="","", TEXT(A39,"mm/yyyy")) -> 08/2024 | P39: =if(C39="","", TEXT(C39,"mm/yyyy")) -> 08/2024 | Q39: {=IFERROR(XLOOKUP(N39,'Classificação'!A:A,'Classificação'!B:B),"")} -> DESPESAS NÃO OPERACIONAIS | R39: {=IFERROR(XLOOKUP(Q39,'Classificação'!B:B,'Classificação'!C:C),"")} -> RESULTADO NÃO OPERACIONAL (+/-) | S39: =iferror(DAY(A39),"") -> 20 | T39: =iferror(MONTH(O39),"") -> 8 | U39: =iferror(YEAR(O39),"") -> 2024 | V39: =if(C39="","", IFERROR(DAY(C39),"")) -> 20 | W39: =if(C39="","",IFERROR(MONTH(C39),"")) -> 8 | X39: =if(C39="","",iferror(YEAR(C39),"")) -> 2024
A40: 45524 | C40: =IF(E40="pago",A40,"") -> 45524 | D40: CANVA - PLATAFORMA ONLINE DE MARKETING | E40: Pago | F40: Cartão de Crédito VISA | G40: BANCO DO BRASIL - 65204-0 | H40: Cartão VISA - PLATAFORMA DE MARKETING ONLINE | I40: 24.25 | K40: =if(E40="pago",(I40-J40),"") -> 24.25 | L40: Mensal | N40: DESPESA COM SISTEMAS | O40: =if(A40="","", TEXT(A40,"mm/yyyy")) -> 08/2024 | P40: =if(C40="","", TEXT(C40,"mm/yyyy")) -> 08/2024 | Q40: {=IFERROR(XLOOKUP(N40,'Classificação'!A:A,'Classificação'!B:B),"")} -> DESPESAS ADMINISTRATIVAS | R40: {=IFERROR(XLOOKUP(Q40,'Classificação'!B:B,'Classificação'!C:C),"")} -> DESPESAS FIXAS (-) | S40: =iferror(DAY(A40),"") -> 20 | T40: =iferror(MONTH(O40),"") -> 8 | U40: =iferror(YEAR(O40),"") -> 2024 | V40: =if(C40="","", IFERROR(DAY(C40),"")) -> 20 | W40: =if(C40="","",IFERROR(MONTH(C40),"")) -> 8 | X40: =if(C40="","",iferror(YEAR(C40),"")) -> 2024
...

Sheet Lançamentos de receitas
A1: Vencimento | B1: Fornecedor | C1: Banco/conta | D1: Descrição | E1: Valor recebido | F1: SITUAÇÃO | G1: PREVISÃO DO RECEBIMENTO | H1: DIA DO RECEBIMENTO | I1: MES DO RECEBIMENTO | J1: ANO DO RECEBIMENTO | K1: MES ANO
A2: 45505 | B2: MERCADO LIVRE LIVRE FARMEL | C2: BANCO DO BRASIL - 65204-0 | D2: VENDAS MERCADO LIVRE FARMEL | E2: 4377.26 | F2: TRANSFERÊNCIA | G2: 45505 | H2: =if(A2="","", iferror(DAY(A2),"")) -> 1 | I2: =if(A2="","", IFERROR(MONTH(A2),"")) -> 8 | J2: =if(A2="","", IFERROR(year(A2),"")) -> 2024 | K2: =TEXT(A2,"mm/yyyy") -> 08/2024
A3: 45505 | B3: MERCADO LIVRE LIVRE FARMEL | C3: BANCO DO BRASIL - 65204-0 | D3: VENDAS MERCADO LIVRE FARMEL | E3: 1629.46 | F3: TRANSFERÊNCIA | G3: 45505 | H3: =if(A3="","", iferror(DAY(A3),"")) -> 1 | I3: =if(A3="","", IFERROR(MONTH(A3),"")) -> 8 | J3: =if(A3="","", IFERROR(year(A3),"")) -> 2024 | K3: =TEXT(A3,"mm/yyyy") -> 08/2024
A4: 45505 | B4: MERCADO LIVRE SINCE | C4: MERCADO PAGO SINCE - 9511092439-1 | D4: VENDAS MERCADO LIVRE SINCE | E4: 886.86 | F4: PAGO | G4: 45505 | H4: =if(A4="","", iferror(DAY(A4),"")) -> 1 | I4: =if(A4="","", IFERROR(MONTH(A4),"")) -> 8 | J4: =if(A4="","", IFERROR(year(A4),"")) -> 2024 | K4: =TEXT(A4,"mm/yyyy") -> 08/2024
A5: 45505 | B5: AMERICANAS | C5: BANCO DO BRASIL - 65204-0 | D5: VENDAS AMERICANAS | E5: 122.98 | F5: TRANSFERÊNCIA | G5: 45505 | H5: =if(A5="","", iferror(DAY(A5),"")) -> 1 | I5: =if(A5="","", IFERROR(MONTH(A5),"")) -> 8 | J5: =if(A5="","", IFERROR(year(A5),"")) -> 2024 | K5: =TEXT(A5,"mm/yyyy") -> 08/2024
A6: 45505 | B6: AMERICANAS | C6: BANCO DO BRASIL - 65204-0 | D6: VENDAS AMERICANAS | E6: 588.82 | F6: TRANSFERÊNCIA | G6: 45505 | H6: =if(A6="","", iferror(DAY(A6),"")) -> 1 | I6: =if(A6="","", IFERROR(MONTH(A6),"")) -> 8 | J6: =if(A6="","", IFERROR(year(A6),"")) -> 2024 | K6: =TEXT(A6,"mm/yyyy") -> 08/2024
A7: 45506 | B7: MERCADO LIVRE LIVRE FARMEL | C7: BANCO DO BRASIL - 65204-0 | D7: VENDAS MERCADO LIVRE FARMEL | E7: 2499.56 | F7: TRANSFERÊNCIA | G7: 45506 | H7: =if(A7="","", iferror(DAY(A7),"")) -> 2 | I7: =if(A7="","", IFERROR(MONTH(A7),"")) -> 8 | J7: =if(A7="","", IFERROR(year(A7),"")) -> 2024 | K7: =TEXT(A7,"mm/yyyy") -> 08/2024
A8: 45506 | B8: MERCADO LIVRE SINCE | C8: MERCADO PAGO SINCE - 9511092439-1 | D8: VENDAS MERCADO LIVRE SINCE | E8: 179.63 | F8: PAGO | G8: 45506 | H8: =if(A8="","", iferror(DAY(A8),"")) -> 2 | I8: =if(A8="","", IFERROR(MONTH(A8),"")) -> 8 | J8: =if(A8="","", IFERROR(year(A8),"")) -> 2024 | K8: =TEXT(A8,"mm/yyyy") -> 08/2024
A9: 45507 | B9: MERCADO LIVRE LIVRE FARMEL | C9: BANCO DO BRASIL - 65204-0 | D9: VENDAS MERCADO LIVRE FARMEL | E9: 3247.92 | F9: TRANSFERÊNCIA | G9: 45507 | H9: =if(A9="","", iferror(DAY(A9),"")) -> 3 | I9: =if(A9="","", IFERROR(MONTH(A9),"")) -> 8 | J9: =if(A9="","", IFERROR(year(A9),"")) -> 2024 | K9: =TEXT(A9,"mm/yyyy") -> 08/2024
A10: 45507 | B10: MERCADO LIVRE SINCE | C10: MERCADO PAGO SINCE - 9511092439-1 | D10: VENDAS MERCADO LIVRE SINCE | E10: 1205.61 | F10: PAGO | G10: 45507 | H10: =if(A10="","", iferror(DAY(A10),"")) -> 3 | I10: =if(A10="","", IFERROR(MONTH(A10),"")) -> 8 | J10: =if(A10="","", IFERROR(year(A10),"")) -> 2024 | K10: =TEXT(A10,"mm/yyyy") -> 08/2024
A11: 45508 | B11: MERCADO LIVRE LIVRE FARMEL | C11: BANCO DO BRASIL - 65204-0 | D11: VENDAS MERCADO LIVRE FARMEL | E11: 1407.97 | F11: TRANSFERÊNCIA | G11: 45508 | H11: =if(A11="","", iferror(DAY(A11),"")) -> 4 | I11: =if(A11="","", IFERROR(MONTH(A11),"")) -> 8 | J11: =if(A11="","", IFERROR(year(A11),"")) -> 2024 | K11: =TEXT(A11,"mm/yyyy") -> 08/2024
A12: 45508 | B12: MERCADO LIVRE SINCE | C12: MERCADO PAGO SINCE - 9511092439-1 | D12: VENDAS MERCADO LIVRE SINCE | E12: 908.67 | F12: PAGO | G12: 45508 | H12: =if(A12="","", iferror(DAY(A12),"")) -> 4 | I12: =if(A12="","", IFERROR(MONTH(A12),"")) -> 8 | J12: =if(A12="","", IFERROR(year(A12),"")) -> 2024 | K12: =TEXT(A12,"mm/yyyy") -> 08/2024
A13: 45509 | B13: MERCADO LIVRE LIVRE FARMEL | C13: BANCO DO BRASIL - 65204-0 | D13: VENDAS MERCADO LIVRE FARMEL | E13: 626.33 | F13: TRANSFERÊNCIA | G13: 45509 | H13: =if(A13="","", iferror(DAY(A13),"")) -> 5 | I13: =if(A13="","", IFERROR(MONTH(A13),"")) -> 8 | J13: =if(A13="","", IFERROR(year(A13),"")) -> 2024 | K13: =TEXT(A13,"mm/yyyy") -> 08/2024
... A1466: 46146 | B1466: AMAZON | C1466: BANCO DO BRASIL - 65204-0 | D1466: VENDAS AMAZON | E1466: 5767 | F1466: ABERTO | G1466: 46146 | H1466: =if(A1466="","", iferror(DAY(A1466),"")) -> 4 | I1466: =if(A1466="","", IFERROR(MONTH(A1466),"")) -> 5 | J1466: =if(A1466="","", IFERROR(year(A1466),"")) -> 2026 | K1466: =TEXT(A1466,"mm/yyyy") -> 05/2026
H1467: =if(A1467="","", iferror(DAY(A1467),"")) | I1467: =if(A1467="","", IFERROR(MONTH(A1467),"")) | J1467: =if(A1467="","", IFERROR(year(A1467),"")) | K1467: =TEXT(A1467,"mm/yyyy") -> 12/1899
H1468: =if(A1468="","", iferror(DAY(A1468),"")) | I1468: =if(A1468="","", IFERROR(MONTH(A1468),"")) | J1468: =if(A1468="","", IFERROR(year(A1468),"")) | K1468: =TEXT(A1468,"mm/yyyy") -> 12/1899
H1469: =if(A1469="","", iferror(DAY(A1469),"")) | I1469: =if(A1469="","", IFERROR(MONTH(A1469),"")) | J1469: =if(A1469="","", IFERROR(year(A1469),"")) | K1469: =TEXT(A1469,"mm/yyyy") -> 12/1899
H1470: =if(A1470="","", iferror(DAY(A1470),"")) | I1470: =if(A1470="","", IFERROR(MONTH(A1470),"")) | J1470: =if(A1470="","", IFERROR(year(A1470),"")) | K1470: =TEXT(A1470,"mm/yyyy") -> 12/1899
H1471: =if(A1471="","", iferror(DAY(A1471),"")) | I1471: =if(A1471="","", IFERROR(MONTH(A1471),"")) | J1471: =if(A1471="","", IFERROR(year(A1471),"")) | K1471: =TEXT(A1471,"mm/yyyy") -> 12/1899
H1472: =if(A1472="","", iferror(DAY(A1472),"")) | I1472: =if(A1472="","", IFERROR(MONTH(A1472),"")) | J1472: =if(A1472="","", IFERROR(year(A1472),"")) | K1472: =TEXT(A1472,"mm/yyyy") -> 12/1899
H1473: =if(A1473="","", iferror(DAY(A1473),"")) | I1473: =if(A1473="","", IFERROR(MONTH(A1473),"")) | J1473: =if(A1473="","", IFERROR(year(A1473),"")) | K1473: =TEXT(A1473,"mm/yyyy") -> 12/1899
H1474: =if(A1474="","", iferror(DAY(A1474),"")) | I1474: =if(A1474="","", IFERROR(MONTH(A1474),"")) | J1474: =if(A1474="","", IFERROR(year(A1474),"")) | K1474: =TEXT(A1474,"mm/yyyy") -> 12/1899
H1475: =if(A1475="","", iferror(DAY(A1475),"")) | I1475: =if(A1475="","", IFERROR(MONTH(A1475),"")) | J1475: =if(A1475="","", IFERROR(year(A1475),"")) | K1475: =TEXT(A1475,"mm/yyyy") -> 12/1899
H1476: =if(A1476="","", iferror(DAY(A1476),"")) | I1476: =if(A1476="","", IFERROR(MONTH(A1476),"")) | J1476: =if(A1476="","", IFERROR(year(A1476),"")) | K1476: =TEXT(A1476,"mm/yyyy") -> 12/1899
H1477: =if(A1477="","", iferror(DAY(A1477),"")) | I1477: =if(A1477="","", IFERROR(MONTH(A1477),"")) | J1477: =if(A1477="","", IFERROR(year(A1477),"")) | K1477: =TEXT(A1477,"mm/yyyy") -> 12/1899
H1478: =if(A1478="","", iferror(DAY(A1478),"")) | I1478: =if(A1478="","", IFERROR(MONTH(A1478),"")) | J1478: =if(A1478="","", IFERROR(year(A1478),"")) | K1478: =TEXT(A1478,"mm/yyyy") -> 12/1899
... H1999: =if(A1999="","", iferror(DAY(A1999),"")) | I1999: =if(A1999="","", IFERROR(MONTH(A1999),"")) | J1999: =if(A1999="","", IFERROR(year(A1999),"")) | K1999: =TEXT(A1999,"mm/yyyy") -> 12/1899

Sheet Simulador de caixa
A1: MÊS | B1: 2026
A2: ANO | B2: 3
A4: DATA | C4: VALOR TRANSFERIDO PARA A CONTA BB | D4: VALOR PAGO DA CONTA SINCE+VALOR PAGO DA CONTA FARMEL | E4: VALOR LIBERADO | F4: VALOR A RECEBER | G4: ENTRADAS TOTAIS | H4: DESPESAS PAGAS | I4: DESPESAS EM ABERTO | J4: DESPESAS AGENDADAS | K4: DESPESAS TOTAIS | L4: ENTRADAS TOTAIS-DESPESAS TOTAIS | M4: SALDO FINAL
A5: 1 | B5: =SUMIFS('COLOQUE AQUI OS SALDOS DAS CONT'!$B:$B,'COLOQUE AQUI OS SALDOS DAS CONT'!$D:$D,$A$5,'COLOQUE AQUI OS SALDOS DAS CONT'!$E:$E,$B$2,'COLOQUE AQUI OS SALDOS DAS CONT'!$F:$F,$B$1) -> 109736.1 | C5: =SUMIFS('Lançamentos de receitas'!$E:$E,'Lançamentos de receitas'!$C:$C,'Contas dos banco'!$C$2,'Lançamentos de receitas'!$H:$H,A5,'Lançamentos de receitas'!$I:$I,$B$2,'Lançamentos de receitas'!$J:$J,$B$1,'Lançamentos de receitas'!$F:$F,"TRANSFERÊNCIA") -> 2615.78 | D5: =+SUMIFS('Lançamentos de receitas'!$E:$E,'Lançamentos de receitas'!$C:$C,'Contas dos banco'!$C$3,'Lançamentos de receitas'!$H:$H,A5,'Lançamentos de receitas'!$I:$I,$B$2,'Lançamentos de receitas'!$J:$J,$B$1,'Lançamentos de receitas'!$F:$F,"PAGO")+SUMIFS('Lançamentos de receitas'!$E:$E,'Lançamentos de receitas'!$C:$C,'Contas dos banco'!$C$4,'Lançamentos de receitas'!$H:$H,A5,'Lançamentos de receitas'!$I:$I,$B$2,'Lançamentos de receitas'!$J:$J,$B$1,'Lançamentos de receitas'!$F:$F,"PAGO") -> 4887.4 | E5: =+SUMIFS('Lançamentos de receitas'!$E:$E,'Lançamentos de receitas'!$F:$F,"liberado",'Lançamentos de receitas'!$H:$H,$A5,'Lançamentos de receitas'!$I:$I,$B$2,'Lançamentos de receitas'!$J:$J,$B$1) -> 0 | F5: =SUMIFS('Lançamentos de receitas'!$E:$E,'Lançamentos de receitas'!$F:$F,"aberto",'Lançamentos de receitas'!$H:$H,$A5,'Lançamentos de receitas'!$I:$I,$B$2,'Lançamentos de receitas'!$J:$J,$B$1) -> 0 | G5: =C5+E5+F5+D5 -> 7503.18 | H5: =SUMIFS('Lançamentos de despesas'!$I:$I,'Lançamentos de despesas'!$E:$E,"pago",'Lançamentos de despesas'!$V:$V,$A5,'Lançamentos de despesas'!$W:$W,$B$2,'Lançamentos de despesas'!$X:$X,$B$1) -> 0 | I5: =SUMIFs('Lançamentos de despesas'!$I:$I,'Lançamentos de despesas'!$E:$E,"aberto",'Lançamentos de despesas'!$S:$S,A5,'Lançamentos de despesas'!$T:$T,$B$2,'Lançamentos de despesas'!$U:$U,$B$1) -> 0 | J5: =SUMIFs('Lançamentos de despesas'!$I:$I,'Lançamentos de despesas'!$E:$E,"agendado",'Lançamentos de despesas'!$S:$S,A5,'Lançamentos de despesas'!$T:$T,$B$2,'Lançamentos de despesas'!$U:$U,$B$1) -> 0 | K5: =H5+I5+J5 -> 0 | L5: =G5-K5 -> 7503.18 | M5: =L5+B5 -> 117239.28
A6: 2 | B6: =M5 -> 117239.28 | C6: =SUMIFS('Lançamentos de receitas'!$E:$E,'Lançamentos de receitas'!$C:$C,'Contas dos banco'!$C$2,'Lançamentos de receitas'!$H:$H,A6,'Lançamentos de receitas'!$I:$I,$B$2,'Lançamentos de receitas'!$J:$J,$B$1,'Lançamentos de receitas'!$F:$F,"TRANSFERÊNCIA") -> 109.72 | D6: =+SUMIFS('Lançamentos de receitas'!$E:$E,'Lançamentos de receitas'!$C:$C,'Contas dos banco'!$C$3,'Lançamentos de receitas'!$H:$H,A6,'Lançamentos de receitas'!$I:$I,$B$2,'Lançamentos de receitas'!$J:$J,$B$1,'Lançamentos de receitas'!$F:$F,"PAGO")+SUMIFS('Lançamentos de receitas'!$E:$E,'Lançamentos de receitas'!$C:$C,'Contas dos banco'!$C$4,'Lançamentos de receitas'!$H:$H,A6,'Lançamentos de receitas'!$I:$I,$B$2,'Lançamentos de receitas'!$J:$J,$B$1,'Lançamentos de receitas'!$F:$F,"PAGO") -> 226.04 | E6: =+SUMIFS('Lançamentos de receitas'!$E:$E,'Lançamentos de receitas'!$F:$F,"liberado",'Lançamentos de receitas'!$H:$H,$A6,'Lançamentos de receitas'!$I:$I,$B$2,'Lançamentos de receitas'!$J:$J,$B$1) -> 0 | F6: =SUMIFS('Lançamentos de receitas'!$E:$E,'Lançamentos de receitas'!$F:$F,"aberto",'Lançamentos de receitas'!$H:$H,$A6,'Lançamentos de receitas'!$I:$I,$B$2,'Lançamentos de receitas'!$J:$J,$B$1) -> 0 | G6: =C6+E6+F6+D6 -> 335.76 | H6: =SUMIFS('Lançamentos de despesas'!$I:$I,'Lançamentos de despesas'!$E:$E,"pago",'Lançamentos de despesas'!$V:$V,$A6,'Lançamentos de despesas'!$W:$W,$B$2,'Lançamentos de despesas'!$X:$X,$B$1) -> 7283.42 | I6: =SUMIFs('Lançamentos de despesas'!$I:$I,'Lançamentos de despesas'!$E:$E,"aberto",'Lançamentos de despesas'!$S:$S,A6,'Lançamentos de despesas'!$T:$T,$B$2,'Lançamentos de despesas'!$U:$U,$B$1) -> 0 | J6: =SUMIFs('Lançamentos de despesas'!$I:$I,'Lançamentos de despesas'!$E:$E,"agendado",'Lançamentos de despesas'!$S:$S,A6,'Lançamentos de despesas'!$T:$T,$B$2,'Lançamentos de despesas'!$U:$U,$B$1) -> 0 | K6: =H6+I6+J6 -> 7283.42 | L6: =G6-K6 -> -6947.66 | M6: =L6+M5 -> 110291.62
A7: 3 | B7: =M6 -> 110291.62 | C7: =SUMIFS('Lançamentos de receitas'!$E:$E,'Lançamentos de receitas'!$C:$C,'Contas dos banco'!$C$2,'Lançamentos de receitas'!$H:$H,A7,'Lançamentos de receitas'!$I:$I,$B$2,'Lançamentos de receitas'!$J:$J,$B$1,'Lançamentos de receitas'!$F:$F,"TRANSFERÊNCIA") -> 34441.04 | D7: =+SUMIFS('Lançamentos de receitas'!$E:$E,'Lançamentos de receitas'!$C:$C,'Contas dos banco'!$C$3,'Lançamentos de receitas'!$H:$H,A7,'Lançamentos de receitas'!$I:$I,$B$2,'Lançamentos de receitas'!$J:$J,$B$1,'Lançamentos de receitas'!$F:$F,"PAGO")+SUMIFS('Lançamentos de receitas'!$E:$E,'Lançamentos de receitas'!$C:$C,'Contas dos banco'!$C$4,'Lançamentos de receitas'!$H:$H,A7,'Lançamentos de receitas'!$I:$I,$B$2,'Lançamentos de receitas'!$J:$J,$B$1,'Lançamentos de receitas'!$F:$F,"PAGO") -> 3119.85 | E7: =+SUMIFS('Lançamentos de receitas'!$E:$E,'Lançamentos de receitas'!$F:$F,"liberado",'Lançamentos de receitas'!$H:$H,$A7,'Lançamentos de receitas'!$I:$I,$B$2,'Lançamentos de receitas'!$J:$J,$B$1) -> 0 | F7: =SUMIFS('Lançamentos de receitas'!$E:$E,'Lançamentos de receitas'!$F:$F,"aberto",'Lançamentos de receitas'!$H:$H,$A7,'Lançamentos de receitas'!$I:$I,$B$2,'Lançamentos de receitas'!$J:$J,$B$1) -> 0 | G7: =C7+E7+F7+D7 -> 37560.89 | H7: =SUMIFS('Lançamentos de despesas'!$I:$I,'Lançamentos de despesas'!$E:$E,"pago",'Lançamentos de despesas'!$V:$V,$A7,'Lançamentos de despesas'!$W:$W,$B$2,'Lançamentos de despesas'!$X:$X,$B$1) -> 10408.63 | I7: =SUMIFs('Lançamentos de despesas'!$I:$I,'Lançamentos de despesas'!$E:$E,"aberto",'Lançamentos de despesas'!$S:$S,A7,'Lançamentos de despesas'!$T:$T,$B$2,'Lançamentos de despesas'!$U:$U,$B$1) -> 0 | J7: =SUMIFs('Lançamentos de despesas'!$I:$I,'Lançamentos de despesas'!$E:$E,"agendado",'Lançamentos de despesas'!$S:$S,A7,'Lançamentos de despesas'!$T:$T,$B$2,'Lançamentos de despesas'!$U:$U,$B$1) -> 0 | K7: =H7+I7+J7 -> 10408.63 | L7: =G7-K7 -> 27152.26 | M7: =L7+M6 -> 137443.88
A8: 4 | B8: =M7 -> 137443.88 | C8: =SUMIFS('Lançamentos de receitas'!$E:$E,'Lançamentos de receitas'!$C:$C,'Contas dos banco'!$C$2,'Lançamentos de receitas'!$H:$H,A8,'Lançamentos de receitas'!$I:$I,$B$2,'Lançamentos de receitas'!$J:$J,$B$1,'Lançamentos de receitas'!$F:$F,"TRANSFERÊNCIA") -> 2026.12 | D8: =+SUMIFS('Lançamentos de receitas'!$E:$E,'Lançamentos de receitas'!$C:$C,'Contas dos banco'!$C$3,'Lançamentos de receitas'!$H:$H,A8,'Lançamentos de receitas'!$I:$I,$B$2,'Lançamentos de receitas'!$J:$J,$B$1,'Lançamentos de receitas'!$F:$F,"PAGO")+SUMIFS('Lançamentos de receitas'!$E:$E,'Lançamentos de receitas'!$C:$C,'Contas dos banco'!$C$4,'Lançamentos de receitas'!$H:$H,A8,'Lançamentos de receitas'!$I:$I,$B$2,'Lançamentos de receitas'!$J:$J,$B$1,'Lançamentos de receitas'!$F:$F,"PAGO") -> 4431.24 | E8: =+SUMIFS('Lançamentos de receitas'!$E:$E,'Lançamentos de receitas'!$F:$F,"liberado",'Lançamentos de receitas'!$H:$H,$A8,'Lançamentos de receitas'!$I:$I,$B$2,'Lançamentos de receitas'!$J:$J,$B$1) -> 0 | F8: =SUMIFS('Lançamentos de receitas'!$E:$E,'Lançamentos de receitas'!$F:$F,"aberto",'Lançamentos de receitas'!$H:$H,$A8,'Lançamentos de receitas'!$I:$I,$B$2,'Lançamentos de receitas'!$J:$J,$B$1) -> 0 | G8: =C8+E8+F8+D8 -> 6457.36 | H8: =SUMIFS('Lançamentos de despesas'!$I:$I,'Lançamentos de despesas'!$E:$E,"pago",'Lançamentos de despesas'!$V:$V,$A8,'Lançamentos de despesas'!$W:$W,$B$2,'Lançamentos de despesas'!$X:$X,$B$1) -> 0 | I8: =SUMIFs('Lançamentos de despesas'!$I:$I,'Lançamentos de despesas'!$E:$E,"aberto",'Lançamentos de despesas'!$S:$S,A8,'Lançamentos de despesas'!$T:$T,$B$2,'Lançamentos de despesas'!$U:$U,$B$1) -> 0 | J8: =SUMIFs('Lançamentos de despesas'!$I:$I,'Lançamentos de despesas'!$E:$E,"agendado",'Lançamentos de despesas'!$S:$S,A8,'Lançamentos de despesas'!$T:$T,$B$2,'Lançamentos de despesas'!$U:$U,$B$1) -> 0 | K8: =H8+I8+J8 -> 0 | L8: =G8-K8 -> 6457.36 | M8: =L8+M7 -> 143901.24
A9: 5 | B9: =M8 -> 143901.24 | C9: =SUMIFS('Lançamentos de receitas'!$E:$E,'Lançamentos de receitas'!$C:$C,'Contas dos banco'!$C$2,'Lançamentos de receitas'!$H:$H,A9,'Lançamentos de receitas'!$I:$I,$B$2,'Lançamentos de receitas'!$J:$J,$B$1,'Lançamentos de receitas'!$F:$F,"TRANSFERÊNCIA") -> 1890.17 | D9: =+SUMIFS('Lançamentos de receitas'!$E:$E,'Lançamentos de receitas'!$C:$C,'Contas dos banco'!$C$3,'Lançamentos de receitas'!$H:$H,A9,'Lançamentos de receitas'!$I:$I,$B$2,'Lançamentos de receitas'!$J:$J,$B$1,'Lançamentos de receitas'!$F:$F,"PAGO")+SUMIFS('Lançamentos de receitas'!$E:$E,'Lançamentos de receitas'!$C:$C,'Contas dos banco'!$C$4,'Lançamentos de receitas'!$H:$H,A9,'Lançamentos de receitas'!$I:$I,$B$2,'Lançamentos de receitas'!$J:$J,$B$1,'Lançamentos de receitas'!$F:$F,"PAGO") -> 4815.19 | E9: =+SUMIFS('Lançamentos de receitas'!$E:$E,'Lançamentos de receitas'!$F:$F,"liberado",'Lançamentos de receitas'!$H:$H,$A9,'Lançamentos de receitas'!$I:$I,$B$2,'Lançamentos de receitas'!$J:$J,$B$1) -> 0 | F9: =SUMIFS('Lançamentos de receitas'!$E:$E,'Lançamentos de receitas'!$F:$F,"aberto",'Lançamentos de receitas'!$H:$H,$A9,'Lançamentos de receitas'!$I:$I,$B$2,'Lançamentos de receitas'!$J:$J,$B$1) -> 0 | G9: =C9+E9+F9+D9 -> 6705.36 | H9: =SUMIFS('Lançamentos de despesas'!$I:$I,'Lançamentos de despesas'!$E:$E,"pago",'Lançamentos de despesas'!$V:$V,$A9,'Lançamentos de despesas'!$W:$W,$B$2,'Lançamentos de despesas'!$X:$X,$B$1) -> 0 | I9: =SUMIFs('Lançamentos de despesas'!$I:$I,'Lançamentos de despesas'!$E:$E,"aberto",'Lançamentos de despesas'!$S:$S,A9,'Lançamentos de despesas'!$T:$T,$B$2,'Lançamentos de despesas'!$U:$U,$B$1) -> 0 | J9: =SUMIFs('Lançamentos de despesas'!$I:$I,'Lançamentos de despesas'!$E:$E,"agendado",'Lançamentos de despesas'!$S:$S,A9,'Lançamentos de despesas'!$T:$T,$B$2,'Lançamentos de despesas'!$U:$U,$B$1) -> 0 | K9: =H9+I9+J9 -> 0 | L9: =G9-K9 -> 6705.36 | M9: =L9+M8 -> 150606.6
A10: 6 | B10: =M9 -> 150606.6 | C10: =SUMIFS('Lançamentos de receitas'!$E:$E,'Lançamentos de receitas'!$C:$C,'Contas dos banco'!$C$2,'Lançamentos de receitas'!$H:$H,A10,'Lançamentos de receitas'!$I:$I,$B$2,'Lançamentos de receitas'!$J:$J,$B$1,'Lançamentos de receitas'!$F:$F,"TRANSFERÊNCIA") -> 7639.453 | D10: =+SUMIFS('Lançamentos de receitas'!$E:$E,'Lançamentos de receitas'!$C:$C,'Contas dos banco'!$C$3,'Lançamentos de receitas'!$H:$H,A10,'Lançamentos de receitas'!$I:$I,$B$2,'Lançamentos de receitas'!$J:$J,$B$1,'Lançamentos de receitas'!$F:$F,"PAGO")+SUMIFS('Lançamentos de receitas'!$E:$E,'Lançamentos de receitas'!$C:$C,'Contas dos banco'!$C$4,'Lançamentos de receitas'!$H:$H,A10,'Lançamentos de receitas'!$I:$I,$B$2,'Lançamentos de receitas'!$J:$J,$B$1,'Lançamentos de receitas'!$F:$F,"PAGO") -> 3131.67 | E10: =+SUMIFS('Lançamentos de receitas'!$E:$E,'Lançamentos de receitas'!$F:$F,"liberado",'Lançamentos de receitas'!$H:$H,$A10,'Lançamentos de receitas'!$I:$I,$B$2,'Lançamentos de receitas'!$J:$J,$B$1) -> 0 | F10: =SUMIFS('Lançamentos de receitas'!$E:$E,'Lançamentos de receitas'!$F:$F,"aberto",'Lançamentos de receitas'!$H:$H,$A10,'Lançamentos de receitas'!$I:$I,$B$2,'Lançamentos de receitas'!$J:$J,$B$1) -> 0 | G10: =C10+E10+F10+D10 -> 10771.123 | H10: =SUMIFS('Lançamentos de despesas'!$I:$I,'Lançamentos de despesas'!$E:$E,"pago",'Lançamentos de despesas'!$V:$V,$A10,'Lançamentos de despesas'!$W:$W,$B$2,'Lançamentos de despesas'!$X:$X,$B$1) -> 0 | I10: =SUMIFs('Lançamentos de despesas'!$I:$I,'Lançamentos de despesas'!$E:$E,"aberto",'Lançamentos de despesas'!$S:$S,A10,'Lançamentos de despesas'!$T:$T,$B$2,'Lançamentos de despesas'!$U:$U,$B$1) -> 0 | J10: =SUMIFs('Lançamentos de despesas'!$I:$I,'Lançamentos de despesas'!$E:$E,"agendado",'Lançamentos de despesas'!$S:$S,A10,'Lançamentos de despesas'!$T:$T,$B$2,'Lançamentos de despesas'!$U:$U,$B$1) -> 0 | K10: =H10+I10+J10 -> 0 | L10: =G10-K10 -> 10771.123 | M10: =L10+M9 -> 161377.72
A11: 7 | B11: =M10 -> 161377.72 | C11: =SUMIFS('Lançamentos de receitas'!$E:$E,'Lançamentos de receitas'!$C:$C,'Contas dos banco'!$C$2,'Lançamentos de receitas'!$H:$H,A11,'Lançamentos de receitas'!$I:$I,$B$2,'Lançamentos de receitas'!$J:$J,$B$1,'Lançamentos de receitas'!$F:$F,"TRANSFERÊNCIA") -> 2319.39 | D11: =+SUMIFS('Lançamentos de receitas'!$E:$E,'Lançamentos de receitas'!$C:$C,'Contas dos banco'!$C$3,'Lançamentos de receitas'!$H:$H,A11,'Lançamentos de receitas'!$I:$I,$B$2,'Lançamentos de receitas'!$J:$J,$B$1,'Lançamentos de receitas'!$F:$F,"PAGO")+SUMIFS('Lançamentos de receitas'!$E:$E,'Lançamentos de receitas'!$C:$C,'Contas dos banco'!$C$4,'Lançamentos de receitas'!$H:$H,A11,'Lançamentos de receitas'!$I:$I,$B$2,'Lançamentos de receitas'!$J:$J,$B$1,'Lançamentos de receitas'!$F:$F,"PAGO") -> 2991.85 | E11: =+SUMIFS('Lançamentos de receitas'!$E:$E,'Lançamentos de receitas'!$F:$F,"liberado",'Lançamentos de receitas'!$H:$H,$A11,'Lançamentos de receitas'!$I:$I,$B$2,'Lançamentos de receitas'!$J:$J,$B$1) -> 0 | F11: =SUMIFS('Lançamentos de receitas'!$E:$E,'Lançamentos de receitas'!$F:$F,"aberto",'Lançamentos de receitas'!$H:$H,$A11,'Lançamentos de receitas'!$I:$I,$B$2,'Lançamentos de receitas'!$J:$J,$B$1) -> 0 | G11: =C11+E11+F11+D11 -> 5311.24 | H11: =SUMIFS('Lançamentos de despesas'!$I:$I,'Lançamentos de despesas'!$E:$E,"pago",'Lançamentos de despesas'!$V:$V,$A11,'Lançamentos de despesas'!$W:$W,$B$2,'Lançamentos de despesas'!$X:$X,$B$1) -> 0 | I11: =SUMIFs('Lançamentos de despesas'!$I:$I,'Lançamentos de despesas'!$E:$E,"aberto",'Lançamentos de despesas'!$S:$S,A11,'Lançamentos de despesas'!$T:$T,$B$2,'Lançamentos de despesas'!$U:$U,$B$1) -> 0 | J11: =SUMIFs('Lançamentos de despesas'!$I:$I,'Lançamentos de despesas'!$E:$E,"agendado",'Lançamentos de despesas'!$S:$S,A11,'Lançamentos de despesas'!$T:$T,$B$2,'Lançamentos de despesas'!$U:$U,$B$1) -> 0 | K11: =H11+I11+J11 -> 0 | L11: =G11-K11 -> 5311.24 | M11: =L11+M10 -> 166688.96
A12: 8 | B12: =M11 -> 166688.96 | C12: =SUMIFS('Lançamentos de receitas'!$E:$E,'Lançamentos de receitas'!$C:$C,'Contas dos banco'!$C$2,'Lançamentos de receitas'!$H:$H,A12,'Lançamentos de receitas'!$I:$I,$B$2,'Lançamentos de receitas'!$J:$J,$B$1,'Lançamentos de receitas'!$F:$F,"TRANSFERÊNCIA") -> 2433.91 | D12: =+SUMIFS('Lançamentos de receitas'!$E:$E,'Lançamentos de receitas'!$C:$C,'Contas dos banco'!$C$3,'Lançamentos de receitas'!$H:$H,A12,'Lançamentos de receitas'!$I:$I,$B$2,'Lançamentos de receitas'!$J:$J,$B$1,'Lançamentos de receitas'!$F:$F,"PAGO")+SUMIFS('Lançamentos de receitas'!$E:$E,'Lançamentos de receitas'!$C:$C,'Contas dos banco'!$C$4,'Lançamentos de receitas'!$H:$H,A12,'Lançamentos de receitas'!$I:$I,$B$2,'Lançamentos de receitas'!$J:$J,$B$1,'Lançamentos de receitas'!$F:$F,"PAGO") -> 2726.63 | E12: =+SUMIFS('Lançamentos de receitas'!$E:$E,'Lançamentos de receitas'!$F:$F,"liberado",'Lançamentos de receitas'!$H:$H,$A12,'Lançamentos de receitas'!$I:$I,$B$2,'Lançamentos de receitas'!$J:$J,$B$1) -> 0 | F12: =SUMIFS('Lançamentos de receitas'!$E:$E,'Lançamentos de receitas'!$F:$F,"aberto",'Lançamentos de receitas'!$H:$H,$A12,'Lançamentos de receitas'!$I:$I,$B$2,'Lançamentos de receitas'!$J:$J,$B$1) -> 0 | G12: =C12+E12+F12+D12 -> 5160.54 | H12: =SUMIFS('Lançamentos de despesas'!$I:$I,'Lançamentos de despesas'!$E:$E,"pago",'Lançamentos de despesas'!$V:$V,$A12,'Lançamentos de despesas'!$W:$W,$B$2,'Lançamentos de despesas'!$X:$X,$B$1) -> 0 | I12: =SUMIFs('Lançamentos de despesas'!$I:$I,'Lançamentos de despesas'!$E:$E,"aberto",'Lançamentos de despesas'!$S:$S,A12,'Lançamentos de despesas'!$T:$T,$B$2,'Lançamentos de despesas'!$U:$U,$B$1) -> 0 | J12: =SUMIFs('Lançamentos de despesas'!$I:$I,'Lançamentos de despesas'!$E:$E,"agendado",'Lançamentos de despesas'!$S:$S,A12,'Lançamentos de despesas'!$T:$T,$B$2,'Lançamentos de despesas'!$U:$U,$B$1) -> 0 | K12: =H12+I12+J12 -> 0 | L12: =G12-K12 -> 5160.54 | M12: =L12+M11 -> 171849.5
A13: 9 | B13: =M12 -> 171849.5 | C13: =SUMIFS('Lançamentos de receitas'!$E:$E,'Lançamentos de receitas'!$C:$C,'Contas dos banco'!$C$2,'Lançamentos de receitas'!$H:$H,A13,'Lançamentos de receitas'!$I:$I,$B$2,'Lançamentos de receitas'!$J:$J,$B$1,'Lançamentos de receitas'!$F:$F,"TRANSFERÊNCIA") -> 14647.84 | D13: =+SUMIFS('Lançamentos de receitas'!$E:$E,'Lançamentos de receitas'!$C:$C,'Contas dos banco'!$C$3,'Lançamentos de receitas'!$H:$H,A13,'Lançamentos de receitas'!$I:$I,$B$2,'Lançamentos de receitas'!$J:$J,$B$1,'Lançamentos de receitas'!$F:$F,"PAGO")+SUMIFS('Lançamentos de receitas'!$E:$E,'Lançamentos de receitas'!$C:$C,'Contas dos banco'!$C$4,'Lançamentos de receitas'!$H:$H,A13,'Lançamentos de receitas'!$I:$I,$B$2,'Lançamentos de receitas'!$J:$J,$B$1,'Lançamentos de receitas'!$F:$F,"PAGO") -> 46.53 | E13: =+SUMIFS('Lançamentos de receitas'!$E:$E,'Lançamentos de receitas'!$F:$F,"liberado",'Lançamentos de receitas'!$H:$H,$A13,'Lançamentos de receitas'!$I:$I,$B$2,'Lançamentos de receitas'!$J:$J,$B$1) -> 0 | F13: =SUMIFS('Lançamentos de receitas'!$E:$E,'Lançamentos de receitas'!$F:$F,"aberto",'Lançamentos de receitas'!$H:$H,$A13,'Lançamentos de receitas'!$I:$I,$B$2,'Lançamentos de receitas'!$J:$J,$B$1) -> 0 | G13: =C13+E13+F13+D13 -> 14694.37 | H13: =SUMIFS('Lançamentos de despesas'!$I:$I,'Lançamentos de despesas'!$E:$E,"pago",'Lançamentos de despesas'!$V:$V,$A13,'Lançamentos de despesas'!$W:$W,$B$2,'Lançamentos de despesas'!$X:$X,$B$1) -> 3084.59 | I13: =SUMIFs('Lançamentos de despesas'!$I:$I,'Lançamentos de despesas'!$E:$E,"aberto",'Lançamentos de despesas'!$S:$S,A13,'Lançamentos de despesas'!$T:$T,$B$2,'Lançamentos de despesas'!$U:$U,$B$1) -> 0 | J13: =SUMIFs('Lançamentos de despesas'!$I:$I,'Lançamentos de despesas'!$E:$E,"agendado",'Lançamentos de despesas'!$S:$S,A13,'Lançamentos de despesas'!$T:$T,$B$2,'Lançamentos de despesas'!$U:$U,$B$1) -> 0 | K13: =H13+I13+J13 -> 3084.59 | L13: =G13-K13 -> 11609.78 | M13: =L13+M12 -> 183459.28
A14: 10 | B14: =M13 -> 183459.28 | C14: =SUMIFS('Lançamentos de receitas'!$E:$E,'Lançamentos de receitas'!$C:$C,'Contas dos banco'!$C$2,'Lançamentos de receitas'!$H:$H,A14,'Lançamentos de receitas'!$I:$I,$B$2,'Lançamentos de receitas'!$J:$J,$B$1,'Lançamentos de receitas'!$F:$F,"TRANSFERÊNCIA") -> 1996.75 | D14: =+SUMIFS('Lançamentos de receitas'!$E:$E,'Lançamentos de receitas'!$C:$C,'Contas dos banco'!$C$3,'Lançamentos de receitas'!$H:$H,A14,'Lançamentos de receitas'!$I:$I,$B$2,'Lançamentos de receitas'!$J:$J,$B$1,'Lançamentos de receitas'!$F:$F,"PAGO")+SUMIFS('Lançamentos de receitas'!$E:$E,'Lançamentos de receitas'!$C:$C,'Contas dos banco'!$C$4,'Lançamentos de receitas'!$H:$H,A14,'Lançamentos de receitas'!$I:$I,$B$2,'Lançamentos de receitas'!$J:$J,$B$1,'Lançamentos de receitas'!$F:$F,"PAGO") -> 2631.87 | E14: =+SUMIFS('Lançamentos de receitas'!$E:$E,'Lançamentos de receitas'!$F:$F,"liberado",'Lançamentos de receitas'!$H:$H,$A14,'Lançamentos de receitas'!$I:$I,$B$2,'Lançamentos de receitas'!$J:$J,$B$1) -> 0 | F14: =SUMIFS('Lançamentos de receitas'!$E:$E,'Lançamentos de receitas'!$F:$F,"aberto",'Lançamentos de receitas'!$H:$H,$A14,'Lançamentos de receitas'!$I:$I,$B$2,'Lançamentos de receitas'!$J:$J,$B$1) -> 0 | G14: =C14+E14+F14+D14 -> 4628.62 | H14: =SUMIFS('Lançamentos de despesas'!$I:$I,'Lançamentos de despesas'!$E:$E,"pago",'Lançamentos de despesas'!$V:$V,$A14,'Lançamentos de despesas'!$W:$W,$B$2,'Lançamentos de despesas'!$X:$X,$B$1) -> 7592.09 | I14: =SUMIFs('Lançamentos de despesas'!$I:$I,'Lançamentos de despesas'!$E:$E,"aberto",'Lançamentos de despesas'!$S:$S,A14,'Lançamentos de despesas'!$T:$T,$B$2,'Lançamentos de despesas'!$U:$U,$B$1) -> 0 | J14: =SUMIFs('Lançamentos de despesas'!$I:$I,'Lançamentos de despesas'!$E:$E,"agendado",'Lançamentos de despesas'!$S:$S,A14,'Lançamentos de despesas'!$T:$T,$B$2,'Lançamentos de despesas'!$U:$U,$B$1) -> 0 | K14: =H14+I14+J14 -> 7592.09 | L14: =G14-K14 -> -2963.47 | M14: =L14+M13 -> 180495.81
